Workbook

Sheet FP_rates
B2: team6 run2 | F2: team2 run2 objIT | J2: team2 run2 objOT | N2: team9 run3
C3: FP (below 3 confidence) | D3: FPR | G3: FP (below 3 confidence) | H3: FPR | K3: FP (below 3 confidence) | L3: FPR | O3: FP (below 3 confidence) | P3: FPR
A4: Wazuh (default) | B4: =COUNTIF(wazuh_team6_run2_objIT!$A$2:$A$5000,$A4) -> 288 | C4: =COUNTIFS(wazuh_team6_run2_objIT!$A$2:$A$5000,$A4,wazuh_team6_run2_objIT!$B$2:$B$5000,"<3") -> 273 | D4: =C4/B4 -> 0.94791667 | F4: =COUNTIF(wazuh_team2_run2_objIT!$A$2:$A$5000,$A4) -> 655 | G4: =COUNTIFS(wazuh_team2_run2_objIT!$A$2:$A$5000,$A4,wazuh_team2_run2_objIT!$B$2:$B$5000,"<3") -> 617 | H4: =G4/F4 -> 0.94198473 | J4: =COUNTIF(wazuh_team2_run2_objOT!$A$2:$A$5000,$A4) -> 282 | K4: =COUNTIFS(wazuh_team2_run2_objOT!$A$2:$A$5000,$A4,wazuh_team2_run2_objOT!$B$2:$B$5000,"<3") -> 276 | L4: =K4/J4 -> 0.9787234 | N4: =COUNTIF(wazuh_team9_run3!$A$2:$A$5000,$A4) -> 1506 | O4: =COUNTIFS(wazuh_team9_run3!$A$2:$A$5000,$A4,wazuh_team9_run3!$B$2:$B$5000,"<3") -> 1022 | P4: =O4/N4 -> 0.67861886
A5: Wazuh (custom) | B5: =COUNTIF(wazuh_team6_run2_objIT!$A$2:$A$5000,$A5) -> 20 | C5: =COUNTIFS(wazuh_team6_run2_objIT!$A$2:$A$5000,$A5,wazuh_team6_run2_objIT!$B$2:$B$5000,"<3") -> 14 | D5: =C5/B5 -> 0.7 | F5: =COUNTIF(wazuh_team2_run2_objIT!$A$2:$A$5000,$A5) -> 38 | G5: =COUNTIFS(wazuh_team2_run2_objIT!$A$2:$A$5000,$A5,wazuh_team2_run2_objIT!$B$2:$B$5000,"<3") -> 16 | H5: =G5/F5 -> 0.42105263 | J5: =COUNTIF(wazuh_team2_run2_objOT!$A$2:$A$5000,$A5) -> 5 | K5: =COUNTIFS(wazuh_team2_run2_objOT!$A$2:$A$5000,$A5,wazuh_team2_run2_objOT!$B$2:$B$5000,"<3") -> 0 | L5: =K5/J5 -> 0 | N5: =COUNTIF(wazuh_team9_run3!$A$2:$A$5000,$A5) -> 28 | O5: =COUNTIFS(wazuh_team9_run3!$A$2:$A$5000,$A5,wazuh_team9_run3!$B$2:$B$5000,"<3") -> 21 | P5: =O5/N5 -> 0.75
A6: Vendor A EDR (default) | B6: =COUNTIF(vendor_a_edr_team6_run2!$A$2:$A$5000,$A6) -> 0 | C6: =COUNTIFS(vendor_a_edr_team6_run2!$A$2:$A$5000,$A6,vendor_a_edr_team6_run2!$B$2:$B$5000,"<3") -> 0 | D6: =C6/B6 -> #DIV/0! | F6: =COUNTIF(vendor_a_edr_team2_run2!$A$2:$A$5000,$A6) -> 1 | G6: =COUNTIFS(vendor_a_edr_team2_run2!$A$2:$A$5000,$A6,vendor_a_edr_team2_run2!$B$2:$B$5000,"<3") -> 0 | H6: =G6/F6 -> 0 | J6: =COUNTIF(vendor_a_edr_team6_run2!$A$2:$A$5000,$A6) -> 0 | K6: =COUNTIFS(vendor_a_edr_team6_run2!$A$2:$A$5000,$A6,vendor_a_edr_team6_run2!$B$2:$B$5000,"<3") -> 0 | L6: =K6/J6 -> #DIV/0! | N6: =COUNTIF(vendor_a_edr_team9_run3!$A$2:$A$5000,$A6) -> 2 | O6: =COUNTIFS(vendor_a_edr_team9_run3!$A$2:$A$5000,$A6,vendor_a_edr_team9_run3!$B$2:$B$5000,"<3") -> 0 | P6: =O6/N6 -> 0
A7: Vendor A EDR (IDP) | B7: =COUNTIF(vendor_a_idp_team6_run2!$A$2:$A$5000,$A7) -> 3 | C7: =COUNTIFS(vendor_a_idp_team6_run2!$A$2:$A$5000,$A7,vendor_a_idp_team6_run2!$B$2:$B$5000,"<3") -> 0 | D7: =C7/B7 -> 0 | F7: =COUNTIF(vendor_a_idp_team2_run2!$A$2:$A$5000,$A7) -> 3 | G7: =COUNTIFS(vendor_a_idp_team2_run2!$A$2:$A$5000,$A7,vendor_a_idp_team2_run2!$B$2:$B$5000,"<3") -> 0 | H7: =G7/F7 -> 0 | J7: =COUNTIF(vendor_a_idp_team6_run2!$A$2:$A$5000,$A7) -> 3 | K7: =COUNTIFS(vendor_a_idp_team6_run2!$A$2:$A$5000,$A7,vendor_a_idp_team6_run2!$B$2:$B$5000,"<3") -> 0 | L7: =K7/J7 -> 0 | N7: =COUNTIF(vendor_a_idp_team9_run3!$A$2:$A$5000,$A7) -> 1 | O7: =COUNTIFS(vendor_a_idp_team9_run3!$A$2:$A$5000,$A7,vendor_a_idp_team9_run3!$B$2:$B$5000,"<3") -> 0 | P7: =O7/N7 -> 0
A8: Suricata (custom) | B8: =COUNTIF(wazuh_team6_run2_objIT!$A$2:$A$5000,$A8) -> 9 | C8: =COUNTIFS(wazuh_team6_run2_objIT!$A$2:$A$5000,$A8,wazuh_team6_run2_objIT!$B$2:$B$5000,"<3") -> 0 | D8: =C8/B8 -> 0 | F8: =COUNTIF(wazuh_team2_run2_objIT!$A$2:$A$5000,$A8) -> 51 | G8: =COUNTIFS(wazuh_team2_run2_objIT!$A$2:$A$5000,$A8,wazuh_team2_run2_objIT!$B$2:$B$5000,"<3") -> 8 | H8: =G8/F8 -> 0.15686275 | J8: =COUNTIF(wazuh_team2_run2_objOT!$A$2:$A$5000,$A8) -> 8 | K8: =COUNTIFS(wazuh_team2_run2_objOT!$A$2:$A$5000,$A8,wazuh_team2_run2_objOT!$B$2:$B$5000,"<3") -> 8 | L8: =K8/J8 -> 1 | N8: =COUNTIF(wazuh_team9_run3!$A$2:$A$5000,$A8) -> 117 | O8: =COUNTIFS(wazuh_team9_run3!$A$2:$A$5000,$A8,wazuh_team9_run3!$B$2:$B$5000,"<3") -> 0 | P8: =O8/N8 -> 0
A9: Suricata (ET ruleset) | B9: =COUNTIF(wazuh_team6_run2_objIT!$A$2:$A$5000,$A9) -> 24 | C9: =COUNTIFS(wazuh_team6_run2_objIT!$A$2:$A$5000,$A9,wazuh_team6_run2_objIT!$B$2:$B$5000,"<3") -> 0 | D9: =C9/B9 -> 0 | F9: =COUNTIF(wazuh_team2_run2_objIT!$A$2:$A$5000,$A9) -> 60 | G9: =COUNTIFS(wazuh_team2_run2_objIT!$A$2:$A$5000,$A9,wazuh_team2_run2_objIT!$B$2:$B$5000,"<3") -> 0 | H9: =G9/F9 -> 0 | J9: =COUNTIF(wazuh_team2_run2_objOT!$A$2:$A$5000,$A9) -> 14 | K9: =COUNTIFS(wazuh_team2_run2_objOT!$A$2:$A$5000,$A9,wazuh_team2_run2_objOT!$B$2:$B$5000,"<3") -> 2 | L9: =K9/J9 -> 0.14285714 | N9: =COUNTIF(wazuh_team9_run3!$A$2:$A$5000,$A9) -> 8 | O9: =COUNTIFS(wazuh_team9_run3!$A$2:$A$5000,$A9,wazuh_team9_run3!$B$2:$B$5000,"<3") -> 0 | P9: =O9/N9 -> 0
A10: Vendor B NIDS (default) | B10: =COUNTIF(vendor_b_nids_team6_run2_objIT!$A$2:$A$5000,$A10) -> 15 | C10: =COUNTIFS(vendor_b_nids_team6_run2_objIT!$A$2:$A$5000,$A10,vendor_b_nids_team6_run2_objIT!$B$2:$B$5000,"<3") -> 4 | D10: =C10/B10 -> 0.26666667 | F10: =COUNTIF(vendor_b_nids_team2_run2_objIT!$A$2:$A$5000,$A10) -> 19 | G10: =COUNTIFS(vendor_b_nids_team2_run2_objIT!$A$2:$A$5000,$A10,vendor_b_nids_team2_run2_objIT!$B$2:$B$5000,"<3") -> 5 | H10: =G10/F10 -> 0.26315789 | J10: =COUNTIF(vendor_b_nids_team2_run2_objOT!$A$2:$A$5000,$A10) -> 8 | K10: =COUNTIFS(vendor_b_nids_team2_run2_objOT!$A$2:$A$5000,$A10,vendor_b_nids_team2_run2_objOT!$B$2:$B$5000,"<3") -> 4 | L10: =K10/J10 -> 0.5 | N10: =COUNTIF(vendor_b_nids_team9_run3!$A$2:$A$5000,$A10) -> 9 | O10: =COUNTIFS(vendor_b_nids_team9_run3!$A$2:$A$5000,$A10,vendor_b_nids_team9_run3!$B$2:$B$5000,"<3") -> 2 | P10: =O10/N10 -> 0.22222222
B15: team2 | C15: team6 | D15: team9
A16: Wazuh (default) | B16: =C4/B4 -> 0.94791667 | C16: =(G4+K4)/(F4+J4) -> 0.95304162 | D16: =O4/N4 -> 0.67861886 | I16: team6 run2
A17: Wazuh (custom) | B17: =(C5+C4)/(B5+B4) -> 0.93181818 | C17: =(G5+G4+K5+K4)/(F5+F4+J5+J4) -> 0.92755102 | D17: =(O5+O4)/(N5+N4) -> 0.67992177 | G17: Vendor B NIDS (default) | H17: all | I17: =COUNTIF(vendor_b_nids_team6_run2_objIT!$A$2:$A$5000,$G17) -> 15 | J17: =COUNTIFS(vendor_b_nids_team6_run2_objIT!$A$2:$A$5000,G17,vendor_b_nids_team6_run2_objIT!$B$2:$B$5000,"<3") -> 4 | K17: =J17/I17 -> 0.26666667
A18: Vendor A EDR (default) | B18: 0 | C18: =(G6+K6)/(F6+J6) -> 0 | D18: =O6/N6 -> 0 | G18: Vendor B NIDS (default) | H18: Low | I18: =COUNTIF(vendor_b_nids_team6_run2_objIT!$D$2:$D$5000,$H18) -> 13 | J18: =COUNTIFS(vendor_b_nids_team6_run2_objIT!$D$2:$D$5000,H18,vendor_b_nids_team6_run2_objIT!$B$2:$B$5000,"<3") -> 4 | K18: =J18/I18 -> 0.30769231
A19: Vendor A EDR (IDP) | B19: =C7/B7 -> 0 | C19: =(G7+K7)/(F7+J7) -> 0 | D19: =O7/N7 -> 0 | G19: Vendor B NIDS (default) | H19: Medium | I19: =COUNTIF(vendor_b_nids_team6_run2_objIT!$D$2:$D$5000,$H19) -> 2 | J19: =COUNTIFS(vendor_b_nids_team6_run2_objIT!$D$2:$D$5000,H19,vendor_b_nids_team6_run2_objIT!$B$2:$B$5000,"<3") -> 0 | K19: =J19/I19 -> 0
A20: Suricata (custom) | B20: =(C8+C9)/(B8+B9) -> 0 | C20: =(G8+G9+K8+K9)/(F8+F9+J8+J9) -> 0.13533835 | D20: =(O8+O9)/(N8+N9) -> 0 | G20: Vendor B NIDS (default) | H20: High | I20: =COUNTIF(vendor_b_nids_team6_run2_objIT!$D$2:$D$5000,$H20) -> 0 | J20: =COUNTIFS(vendor_b_nids_team6_run2_objIT!$D$2:$D$5000,H20,vendor_b_nids_team6_run2_objIT!$B$2:$B$5000,"<3") -> 0 | K20: =J20/I20 -> #DIV/0!
A21: Suricata (ET ruleset) | B21: =C9/B9 -> 0 | C21: =(G9+K9)/(F9+J9) -> 0.027027027 | D21: =O9/N9 -> 0
A22: Vendor B NIDS (default) | B22: =C10/B10 -> 0.26666667 | C22: =(G10+K10)/(F10+J10) -> 0.33333333 | D22: =O10/N10 -> 0.22222222

Sheet wazuh_team6_run2_objIT
A1: Rule Origin | B1: Attack Confidence Pentester A | C1: Attack Confidence Pentester B | D1: timestamp UTC+1 | E1: host | F1: severity | G1: level | H1: description | I1: log
A2: Wazuh (default) | B2: 1 | C2: 1 | D2: 45744.661 | E2: CLI1 | F2: low | G2: 3 | H2: Windows Logon Success | I2: "An account was successfully logged on._x000D_ _x000D_ Subject:_x000D_ Security ID: S-1-5-18_x000D_ Account Name: CLI1$_x000D_ Account Domain: PLUMETECH_x000D_ Logon ID: 0x3E7_x000D_ _x000D_ Logon Information:_x000D_ Logon Type: 5_x000D_ Restricted Admin Mode: -_x000D_ Virtual Account: No_x000D_ Elevated Token: Yes_x000D_ _x000D_ Impersonation Level: Impersonation_x000D_ _x000D_ New Logon:_x000D_ Security ID: S-1-5-18_x000D_ Account Name: SYSTEM_x000D_ Account Domain: NT AUTHORITY_x000D_ Logon ID: 0x3E7_x000D_ Linked Logon ID: 0x0_x000D_ Network Account Name: -_x000D_ Network Account Domain: -_x000D_ Logon GUID: {00000000-0000-0000-0000-000000000000}_x000D_ _x000D_ Process Information:_x000D_ Process ID: 0x330_x000D_ Process Name: C:\Windows\System32\services.exe_x000D_ _x000D_ Network Information:_x000D_ Workstation Name: -_x000D_ Source Network Address: -_x000D_ Source Port: -_x000D_ _x000D_ Detailed Authentication Information:_x000D_ Logon Process: Advapi _x000D_ Authentication Package: Negotiate_x000D_ Transited Services: -_x000D_ Package Name (NTLM only): -_x000D_ Key Length: 0_x000D_ _x000D_ This event is generated when a logon session is created. It is generated on the computer that was accessed._x000D_ _x000D_ The subject fields indicate the account on the local system which requested the logon. This is most commonly a service such as the Server service, or a local process such as Winlogon.exe or Services.exe._x000D_ _x000D_ The logon type field indicates the kind of logon that occurred. The most common types are 2 (interactive) and 3 (network)._x000D_ _x000D_ The New Logon fields indicate the account for whom the new logon was created, i.e. the account that was logged on._x000D_ _x000D_ The network fields indicate where a remote logon request originated. Workstation name is not always available and may be left blank in some cases._x000D_ _x000D_ The impersonation level field indicates the extent to which a process in the logon session can impersonate._x000D_ _x000D_ The authentication information fields provide detailed information about this specific logon request._x000D_ - Logon GUID is a unique identifier that can be used to correlate this event with a KDC event._x000D_ - Transited services indicate which intermediate services have participated in this logon request._x000D_ - Package name indicates which sub-protocol was used among the NTLM protocols._x000D_ - Key length indicates the length of the generated session key. This will be 0 if no session key was requested."
A3: Wazuh (default) | B3: 1 | C3: 1 | D3: 45744.661 | E3: CLI1 | F3: low | G3: 3 | H3: Windows Logon Success | I3: "An account was successfully logged on._x000D_ _x000D_ Subject:_x000D_ Security ID: S-1-5-18_x000D_ Account Name: CLI1$_x000D_ Account Domain: PLUMETECH_x000D_ Logon ID: 0x3E7_x000D_ _x000D_ Logon Information:_x000D_ Logon Type: 5_x000D_ Restricted Admin Mode: -_x000D_ Virtual Account: No_x000D_ Elevated Token: Yes_x000D_ _x000D_ Impersonation Level: Impersonation_x000D_ _x000D_ New Logon:_x000D_ Security ID: S-1-5-18_x000D_ Account Name: SYSTEM_x000D_ Account Domain: NT AUTHORITY_x000D_ Logon ID: 0x3E7_x000D_ Linked Logon ID: 0x0_x000D_ Network Account Name: -_x000D_ Network Account Domain: -_x000D_ Logon GUID: {00000000-0000-0000-0000-000000000000}_x000D_ _x000D_ Process Information:_x000D_ Process ID: 0x330_x000D_ Process Name: C:\Windows\System32\services.exe_x000D_ _x000D_ Network Information:_x000D_ Workstation Name: -_x000D_ Source Network Address: -_x000D_ Source Port: -_x000D_ _x000D_ Detailed Authentication Information:_x000D_ Logon Process: Advapi _x000D_ Authentication Package: Negotiate_x000D_ Transited Services: -_x000D_ Package Name (NTLM only): -_x000D_ Key Length: 0_x000D_ _x000D_ This event is generated when a logon session is created. It is generated on the computer that was accessed._x000D_ _x000D_ The subject fields indicate the account on the local system which requested the logon. This is most commonly a service such as the Server service, or a local process such as Winlogon.exe or Services.exe._x000D_ _x000D_ The logon type field indicates the kind of logon that occurred. The most common types are 2 (interactive) and 3 (network)._x000D_ _x000D_ The New Logon fields indicate the account for whom the new logon was created, i.e. the account that was logged on._x000D_ _x000D_ The network fields indicate where a remote logon request originated. Workstation name is not always available and may be left blank in some cases._x000D_ _x000D_ The impersonation level field indicates the extent to which a process in the logon session can impersonate._x000D_ _x000D_ The authentication information fields provide detailed information about this specific logon request._x000D_ - Logon GUID is a unique identifier that can be used to correlate this event with a KDC event._x000D_ - Transited services indicate which intermediate services have participated in this logon request._x000D_ - Package name indicates which sub-protocol was used among the NTLM protocols._x000D_ - Key length indicates the length of the generated session key. This will be 0 if no session key was requested."
A4: Wazuh (default) | B4: 1 | C4: 1 | D4: 45744.661 | E4: FS1 | F4: low | G4: 3 | H4: Windows Logon Success | I4: "An account was successfully logged on._x000D_ _x000D_ Subject:_x000D_ Security ID: S-1-5-18_x000D_ Account Name: FS1$_x000D_ Account Domain: PLUMETECH_x000D_ Logon ID: 0x3E7_x000D_ _x000D_ Logon Information:_x000D_ Logon Type: 5_x000D_ Restricted Admin Mode: -_x000D_ Virtual Account: No_x000D_ Elevated Token: Yes_x000D_ _x000D_ Impersonation Level: Impersonation_x000D_ _x000D_ New Logon:_x000D_ Security ID: S-1-5-18_x000D_ Account Name: SYSTEM_x000D_ Account Domain: NT AUTHORITY_x000D_ Logon ID: 0x3E7_x000D_ Linked Logon ID: 0x0_x000D_ Network Account Name: -_x000D_ Network Account Domain: -_x000D_ Logon GUID: {00000000-0000-0000-0000-000000000000}_x000D_ _x000D_ Process Information:_x000D_ Process ID: 0x330_x000D_ Process Name: C:\Windows\System32\services.exe_x000D_ _x000D_ Network Information:_x000D_ Workstation Name: -_x000D_ Source Network Address: -_x000D_ Source Port: -_x000D_ _x000D_ Detailed Authentication Information:_x000D_ Logon Process: Advapi _x000D_ Authentication Package: Negotiate_x000D_ Transited Services: -_x000D_ Package Name (NTLM only): -_x000D_ Key Length: 0_x000D_ _x000D_ This event is generated when a logon session is created. It is generated on the computer that was accessed._x000D_ _x000D_ The subject fields indicate the account on the local system which requested the logon. This is most commonly a service such as the Server service, or a local process such as Winlogon.exe or Services.exe._x000D_ _x000D_ The logon type field indicates the kind of logon that occurred. The most common types are 2 (interactive) and 3 (network)._x000D_ _x000D_ The New Logon fields indicate the account for whom the new logon was created, i.e. the account that was logged on._x000D_ _x000D_ The network fields indicate where a remote logon request originated. Workstation name is not always available and may be left blank in some cases._x000D_ _x000D_ The impersonation level field indicates the extent to which a process in the logon session can impersonate._x000D_ _x000D_ The authentication information fields provide detailed information about this specific logon request._x000D_ - Logon GUID is a unique identifier that can be used to correlate this event with a KDC event._x000D_ - Transited services indicate which intermediate services have participated in this logon request._x000D_ - Package name indicates which sub-protocol was used among the NTLM protocols._x000D_ - Key length indicates the length of the generated session key. This will be 0 if no session key was requested."
A5: Wazuh (default) | B5: 1 | C5: 1 | D5: 45744.661 | E5: CLI1 | F5: low | G5: 3 | H5: Windows Logon Success | I5: "An account was successfully logged on._x000D_ _x000D_ Subject:_x000D_ Security ID: S-1-5-18_x000D_ Account Name: CLI1$_x000D_ Account Domain: PLUMETECH_x000D_ Logon ID: 0x3E7_x000D_ _x000D_ Logon Information:_x000D_ Logon Type: 5_x000D_ Restricted Admin Mode: -_x000D_ Virtual Account: No_x000D_ Elevated Token: Yes_x000D_ _x000D_ Impersonation Level: Impersonation_x000D_ _x000D_ New Logon:_x000D_ Security ID: S-1-5-18_x000D_ Account Name: SYSTEM_x000D_ Account Domain: NT AUTHORITY_x000D_ Logon ID: 0x3E7_x000D_ Linked Logon ID: 0x0_x000D_ Network Account Name: -_x000D_ Network Account Domain: -_x000D_ Logon GUID: {00000000-0000-0000-0000-000000000000}_x000D_ _x000D_ Process Information:_x000D_ Process ID: 0x330_x000D_ Process Name: C:\Windows\System32\services.exe_x000D_ _x000D_ Network Information:_x000D_ Workstation Name: -_x000D_ Source Network Address: -_x000D_ Source Port: -_x000D_ _x000D_ Detailed Authentication Information:_x000D_ Logon Process: Advapi _x000D_ Authentication Package: Negotiate_x000D_ Transited Services: -_x000D_ Package Name (NTLM only): -_x000D_ Key Length: 0_x000D_ _x000D_ This event is generated when a logon session is created. It is generated on the computer that was accessed._x000D_ _x000D_ The subject fields indicate the account on the local system which requested the logon. This is most commonly a service such as the Server service, or a local process such as Winlogon.exe or Services.exe._x000D_ _x000D_ The logon type field indicates the kind of logon that occurred. The most common types are 2 (interactive) and 3 (network)._x000D_ _x000D_ The New Logon fields indicate the account for whom the new logon was created, i.e. the account that was logged on._x000D_ _x000D_ The network fields indicate where a remote logon request originated. Workstation name is not always available and may be left blank in some cases._x000D_ _x000D_ The impersonation level field indicates the extent to which a process in the logon session can impersonate._x000D_ _x000D_ The authentication information fields provide detailed information about this specific logon request._x000D_ - Logon GUID is a unique identifier that can be used to correlate this event with a KDC event._x000D_ - Transited services indicate which intermediate services have participated in this logon request._x000D_ - Package name indicates which sub-protocol was used among the NTLM protocols._x000D_ - Key length indicates the length of the generated session key. This will be 0 if no session key was requested."
A6: Wazuh (default) | B6: 1 | C6: 1 | D6: 45744.661 | E6: CLI1 | F6: low | G6: 3 | H6: Windows Logon Success | I6: "An account was successfully logged on._x000D_ _x000D_ Subject:_x000D_ Security ID: S-1-5-18_x000D_ Account Name: CLI1$_x000D_ Account Domain: PLUMETECH_x000D_ Logon ID: 0x3E7_x000D_ _x000D_ Logon Information:_x000D_ Logon Type: 5_x000D_ Restricted Admin Mode: -_x000D_ Virtual Account: No_x000D_ Elevated Token: Yes_x000D_ _x000D_ Impersonation Level: Impersonation_x000D_ _x000D_ New Logon:_x000D_ Security ID: S-1-5-18_x000D_ Account Name: SYSTEM_x000D_ Account Domain: NT AUTHORITY_x000D_ Logon ID: 0x3E7_x000D_ Linked Logon ID: 0x0_x000D_ Network Account Name: -_x000D_ Network Account Domain: -_x000D_ Logon GUID: {00000000-0000-0000-0000-000000000000}_x000D_ _x000D_ Process Information:_x000D_ Process ID: 0x330_x000D_ Process Name: C:\Windows\System32\services.exe_x000D_ _x000D_ Network Information:_x000D_ Workstation Name: -_x000D_ Source Network Address: -_x000D_ Source Port: -_x000D_ _x000D_ Detailed Authentication Information:_x000D_ Logon Process: Advapi _x000D_ Authentication Package: Negotiate_x000D_ Transited Services: -_x000D_ Package Name (NTLM only): -_x000D_ Key Length: 0_x000D_ _x000D_ This event is generated when a logon session is created. It is generated on the computer that was accessed._x000D_ _x000D_ The subject fields indicate the account on the local system which requested the logon. This is most commonly a service such as the Server service, or a local process such as Winlogon.exe or Services.exe._x000D_ _x000D_ The logon type field indicates the kind of logon that occurred. The most common types are 2 (interactive) and 3 (network)._x000D_ _x000D_ The New Logon fields indicate the account for whom the new logon was created, i.e. the account that was logged on._x000D_ _x000D_ The network fields indicate where a remote logon request originated. Workstation name is not always available and may be left blank in some cases._x000D_ _x000D_ The impersonation level field indicates the extent to which a process in the logon session can impersonate._x000D_ _x000D_ The authentication information fields provide detailed information about this specific logon request._x000D_ - Logon GUID is a unique identifier that can be used to correlate this event with a KDC event._x000D_ - Transited services indicate which intermediate services have participated in this logon request._x000D_ - Package name indicates which sub-protocol was used among the NTLM protocols._x000D_ - Key length indicates the length of the generated session key. This will be 0 if no session key was requested."
A7: Wazuh (default) | B7: 1 | C7: 1 | D7: 45744.661 | E7: FS1 | F7: low | G7: 3 | H7: Windows Logon Success | I7: "An account was successfully logged on._x000D_ _x000D_ Subject:_x000D_ Security ID: S-1-5-18_x000D_ Account Name: FS1$_x000D_ Account Domain: PLUMETECH_x000D_ Logon ID: 0x3E7_x000D_ _x000D_ Logon Information:_x000D_ Logon Type: 5_x000D_ Restricted Admin Mode: -_x000D_ Virtual Account: No_x000D_ Elevated Token: Yes_x000D_ _x000D_ Impersonation Level: Impersonation_x000D_ _x000D_ New Logon:_x000D_ Security ID: S-1-5-18_x000D_ Account Name: SYSTEM_x000D_ Account Domain: NT AUTHORITY_x000D_ Logon ID: 0x3E7_x000D_ Linked Logon ID: 0x0_x000D_ Network Account Name: -_x000D_ Network Account Domain: -_x000D_ Logon GUID: {00000000-0000-0000-0000-000000000000}_x000D_ _x000D_ Process Information:_x000D_ Process ID: 0x330_x000D_ Process Name: C:\Windows\System32\services.exe_x000D_ _x000D_ Network Information:_x000D_ Workstation Name: -_x000D_ Source Network Address: -_x000D_ Source Port: -_x000D_ _x000D_ Detailed Authentication Information:_x000D_ Logon Process: Advapi _x000D_ Authentication Package: Negotiate_x000D_ Transited Services: -_x000D_ Package Name (NTLM only): -_x000D_ Key Length: 0_x000D_ _x000D_ This event is generated when a logon session is created. It is generated on the computer that was accessed._x000D_ _x000D_ The subject fields indicate the account on the local system which requested the logon. This is most commonly a service such as the Server service, or a local process such as Winlogon.exe or Services.exe._x000D_ _x000D_ The logon type field indicates the kind of logon that occurred. The most common types are 2 (interactive) and 3 (network)._x000D_ _x000D_ The New Logon fields indicate the account for whom the new logon was created, i.e. the account that was logged on._x000D_ _x000D_ The network fields indicate where a remote logon request originated. Workstation name is not always available and may be left blank in some cases._x000D_ _x000D_ The impersonation level field indicates the extent to which a process in the logon session can impersonate._x000D_ _x000D_ The authentication information fields provide detailed information about this specific logon request._x000D_ - Logon GUID is a unique identifier that can be used to correlate this event with a KDC event._x000D_ - Transited services indicate which intermediate services have participated in this logon request._x000D_ - Package name indicates which sub-protocol was used among the NTLM protocols._x000D_ - Key length indicates the length of the generated session key. This will be 0 if no session key was requested."
A8: Wazuh (default) | B8: 1 | C8: 1 | D8: 45744.661 | E8: FS1 | F8: low | G8: 3 | H8: Windows Logon Success | I8: "An account was successfully logged on._x000D_ _x000D_ Subject:_x000D_ Security ID: S-1-5-18_x000D_ Account Name: FS1$_x000D_ Account Domain: PLUMETECH_x000D_ Logon ID: 0x3E7_x000D_ _x000D_ Logon Information:_x000D_ Logon Type: 5_x000D_ Restricted Admin Mode: -_x000D_ Virtual Account: No_x000D_ Elevated Token: Yes_x000D_ _x000D_ Impersonation Level: Impersonation_x000D_ _x000D_ New Logon:_x000D_ Security ID: S-1-5-18_x000D_ Account Name: SYSTEM_x000D_ Account Domain: NT AUTHORITY_x000D_ Logon ID: 0x3E7_x000D_ Linked Logon ID: 0x0_x000D_ Network Account Name: -_x000D_ Network Account Domain: -_x000D_ Logon GUID: {00000000-0000-0000-0000-000000000000}_x000D_ _x000D_ Process Information:_x000D_ Process ID: 0x330_x000D_ Process Name: C:\Windows\System32\services.exe_x000D_ _x000D_ Network Information:_x000D_ Workstation Name: -_x000D_ Source Network Address: -_x000D_ Source Port: -_x000D_ _x000D_ Detailed Authentication Information:_x000D_ Logon Process: Advapi _x000D_ Authentication Package: Negotiate_x000D_ Transited Services: -_x000D_ Package Name (NTLM only): -_x000D_ Key Length: 0_x000D_ _x000D_ This event is generated when a logon session is created. It is generated on the computer that was accessed._x000D_ _x000D_ The subject fields indicate the account on the local system which requested the logon. This is most commonly a service such as the Server service, or a local process such as Winlogon.exe or Services.exe._x000D_ _x000D_ The logon type field indicates the kind of logon that occurred. The most common types are 2 (interactive) and 3 (network)._x000D_ _x000D_ The New Logon fields indicate the account for whom the new logon was created, i.e. the account that was logged on._x000D_ _x000D_ The network fields indicate where a remote logon request originated. Workstation name is not always available and may be left blank in some cases._x000D_ _x000D_ The impersonation level field indicates the extent to which a process in the logon session can impersonate._x000D_ _x000D_ The authentication information fields provide detailed information about this specific logon request._x000D_ - Logon GUID is a unique identifier that can be used to correlate this event with a KDC event._x000D_ - Transited services indicate which intermediate services have participated in this logon request._x000D_ - Package name indicates which sub-protocol was used among the NTLM protocols._x000D_ - Key length indicates the length of the generated session key. This will be 0 if no session key was requested."
A9: Wazuh (default) | B9: 1 | C9: 1 | D9: 45744.661 | E9: OTDC1 | F9: low | G9: 3 | H9: Windows Logon Success | I9: "An account was successfully logged on._x000D_ _x000D_ Subject:_x000D_ Security ID: S-1-0-0_x000D_ Account Name: -_x000D_ Account Domain: -_x000D_ Logon ID: 0x0_x000D_ _x000D_ Logon Information:_x000D_ Logon Type: 3_x000D_ Restricted Admin Mode: -_x000D_ Virtual Account: No_x000D_ Elevated Token: Yes_x000D_ _x000D_ Impersonation Level: Impersonation_x000D_ _x000D_ New Logon:_x000D_ Security ID: S-1-5-18_x000D_ Account Name: OTDC1$_x000D_ Account Domain: PLUMETECH-OT.LOCAL_x000D_ Logon ID: 0x1B9F3A_x000D_ Linked Logon ID: 0x0_x000D_ Network Account Name: -_x000D_ Network Account Domain: -_x000D_ Logon GUID: {f8ce4a99-b918-5581-a01a-8f89eb124c5f}_x000D_ _x000D_ Process Information:_x000D_ Process ID: 0x0_x000D_ Process Name: -_x000D_ _x000D_ Network Information:_x000D_ Workstation Name: -_x000D_ Source Network Address: fe80::3548:80d5:5abe:afc4_x000D_ Source Port: 61062_x000D_ _x000D_ Detailed Authentication Information:_x000D_ Logon Process: Kerberos_x000D_ Authentication Package: Kerberos_x000D_ Transited Services: -_x000D_ Package Name (NTLM only): -_x000D_ Key Length: 0_x000D_ _x000D_ This event is generated when a logon session is created. It is generated on the computer that was accessed._x000D_ _x000D_ The subject fields indicate the account on the local system which requested the logon. This is most commonly a service such as the Server service, or a local process such as Winlogon.exe or Services.exe._x000D_ _x000D_ The logon type field indicates the kind of logon that occurred. The most common types are 2 (interactive) and 3 (network)._x000D_ _x000D_ The New Logon fields indicate the account for whom the new logon was created, i.e. the account that was logged on._x000D_ _x000D_ The network fields indicate where a remote logon request originated. Workstation name is not always available and may be left blank in some cases._x000D_ _x000D_ The impersonation level field indicates the extent to which a process in the logon session can impersonate._x000D_ _x000D_ The authentication information fields provide detailed information about this specific logon request._x000D_ - Logon GUID is a unique identifier that can be used to correlate this event with a KDC event._x000D_ - Transited services indicate which intermediate services have participated in this logon request._x000D_ - Package name indicates which sub-protocol was used among the NTLM protocols._x000D_ - Key length indicates the length of the generated session key. This will be 0 if no session key was requested."
A10: Wazuh (default) | B10: 1 | C10: 1 | D10: 45744.661 | E10: OTDC1 | F10: low | G10: 3 | H10: Windows Logon Success | I10: "An account was successfully logged on._x000D_ _x000D_ Subject:_x000D_ Security ID: S-1-0-0_x000D_ Account Name: -_x000D_ Account Domain: -_x000D_ Logon ID: 0x0_x000D_ _x000D_ Logon Information:_x000D_ Logon Type: 3_x000D_ Restricted Admin Mode: -_x000D_ Virtual Account: No_x000D_ Elevated Token: Yes_x000D_ _x000D_ Impersonation Level: Delegation_x000D_ _x000D_ New Logon:_x000D_ Security ID: S-1-5-18_x000D_ Account Name: OTDC1$_x000D_ Account Domain: PLUMETECH-OT.LOCAL_x000D_ Logon ID: 0x1BA00D_x000D_ Linked Logon ID: 0x0_x000D_ Network Account Name: -_x000D_ Network Account Domain: -_x000D_ Logon GUID: {c6984051-86da-e9fa-4b42-9e76c2f2711b}_x000D_ _x000D_ Process Information:_x000D_ Process ID: 0x0_x000D_ Process Name: -_x000D_ _x000D_ Network Information:_x000D_ Workstation Name: -_x000D_ Source Network Address: fe80::3548:80d5:5abe:afc4_x000D_ Source Port: 61063_x000D_ _x000D_ Detailed Authentication Information:_x000D_ Logon Process: Kerberos_x000D_ Authentication Package: Kerberos_x000D_ Transited Services: -_x000D_ Package Name (NTLM only): -_x000D_ Key Length: 0_x000D_ _x000D_ This event is generated when a logon session is created. It is generated on the computer that was accessed._x000D_ _x000D_ The subject fields indicate the account on the local system which requested the logon. This is most commonly a service such as the Server service, or a local process such as Winlogon.exe or Services.exe._x000D_ _x000D_ The logon type field indicates the kind of logon that occurred. The most common types are 2 (interactive) and 3 (network)._x000D_ _x000D_ The New Logon fields indicate the account for whom the new logon was created, i.e. the account that was logged on._x000D_ _x000D_ The network fields indicate where a remote logon request originated. Workstation name is not always available and may be left blank in some cases._x000D_ _x000D_ The impersonation level field indicates the extent to which a process in the logon session can impersonate._x000D_ _x000D_ The authentication information fields provide detailed information about this specific logon request._x000D_ - Logon GUID is a unique identifier that can be used to correlate this event with a KDC event._x000D_ - Transited services indicate which intermediate services have participated in this logon request._x000D_ - Package name indicates which sub-protocol was used among the NTLM protocols._x000D_ - Key length indicates the length of the generated session key. This will be 0 if no session key was requested."
A11: Wazuh (default) | B11: 1 | C11: 1 | D11: 45744.661 | E11: OTDC1 | F11: low | G11: 3 | H11: Windows Logon Success | I11: "An account was successfully logged on._x000D_ _x000D_ Subject:_x000D_ Security ID: S-1-0-0_x000D_ Account Name: -_x000D_ Account Domain: -_x000D_ Logon ID: 0x0_x000D_ _x000D_ Logon Information:_x000D_ Logon Type: 3_x000D_ Restricted Admin Mode: -_x000D_ Virtual Account: No_x000D_ Elevated Token: Yes_x000D_ _x000D_ Impersonation Level: Impersonation_x000D_ _x000D_ New Logon:_x000D_ Security ID: S-1-5-18_x000D_ Account Name: OTDC1$_x000D_ Account Domain: PLUMETECH-OT.LOCAL_x000D_ Logon ID: 0x1BA0FF_x000D_ Linked Logon ID: 0x0_x000D_ Network Account Name: -_x000D_ Network Account Domain: -_x000D_ Logon GUID: {c6984051-86da-e9fa-4b42-9e76c2f2711b}_x000D_ _x000D_ Process Information:_x000D_ Process ID: 0x0_x000D_ Process Name: -_x000D_ _x000D_ Network Information:_x000D_ Workstation Name: -_x000D_ Source Network Address: ::1_x000D_ Source Port: 0_x000D_ _x000D_ Detailed Authentication Information:_x000D_ Logon Process: Kerberos_x000D_ Authentication Package: Kerberos_x000D_ Transited Services: -_x000D_ Package Name (NTLM only): -_x000D_ Key Length: 0_x000D_ _x000D_ This event is generated when a logon session is created. It is generated on the computer that was accessed._x000D_ _x000D_ The subject fields indicate the account on the local system which requested the logon. This is most commonly a service such as the Server service, or a local process such as Winlogon.exe or Services.exe._x000D_ _x000D_ The logon type field indicates the kind of logon that occurred. The most common types are 2 (interactive) and 3 (network)._x000D_ _x000D_ The New Logon fields indicate the account for whom the new logon was created, i.e. the account that was logged on._x000D_ _x000D_ The network fields indicate where a remote logon request originated. Workstation name is not always available and may be left blank in some cases._x000D_ _x000D_ The impersonation level field indicates the extent to which a process in the logon session can impersonate._x000D_ _x000D_ The authentication information fields provide detailed information about this specific logon request._x000D_ - Logon GUID is a unique identifier that can be used to correlate this event with a KDC event._x000D_ - Transited services indicate which intermediate services have participated in this logon request._x000D_ - Package name indicates which sub-protocol was used among the NTLM protocols._x000D_ - Key length indicates the length of the generated session key. This will be 0 if no session key was requested."
A12: Wazuh (default) | B12: 1 | C12: 1 | D12: 45744.661 | E12: OTDC1 | F12: low | G12: 3 | H12: Windows Logon Success | I12: "An account was successfully logged on._x000D_ _x000D_ Subject:_x000D_ Security ID: S-1-0-0_x000D_ Account Name: -_x000D_ Account Domain: -_x000D_ Logon ID: 0x0_x000D_ _x000D_ Logon Information:_x000D_ Logon Type: 3_x000D_ Restricted Admin Mode: -_x000D_ Virtual Account: No_x000D_ Elevated Token: Yes_x000D_ _x000D_ Impersonation Level: Impersonation_x000D_ _x000D_ New Logon:_x000D_ Security ID: S-1-5-18_x000D_ Account Name: OTDC1$_x000D_ Account Domain: PLUMETECH-OT.LOCAL_x000D_ Logon ID: 0x1BA3AA_x000D_ Linked Logon ID: 0x0_x000D_ Network Account Name: -_x000D_ Network Account Domain: -_x000D_ Logon GUID: {c6984051-86da-e9fa-4b42-9e76c2f2711b}_x000D_ _x000D_ Process Information:_x000D_ Process ID: 0x0_x000D_ Process Name: -_x000D_ _x000D_ Network Information:_x000D_ Workstation Name: -_x000D_ Source Network Address: ::1_x000D_ Source Port: 0_x000D_ _x000D_ Detailed Authentication Information:_x000D_ Logon Process: Kerberos_x000D_ Authentication Package: Kerberos_x000D_ Transited Services: -_x000D_ Package Name (NTLM only): -_x000D_ Key Length: 0_x000D_ _x000D_ This event is generated when a logon session is created. It is generated on the computer that was accessed._x000D_ _x000D_ The subject fields indicate the account on the local system which requested the logon. This is most commonly a service such as the Server service, or a local process such as Winlogon.exe or Services.exe._x000D_ _x000D_ The logon type field indicates the kind of logon that occurred. The most common types are 2 (interactive) and 3 (network)._x000D_ _x000D_ The New Logon fields indicate the account for whom the new logon was created, i.e. the account that was logged on._x000D_ _x000D_ The network fields indicate where a remote logon request originated. Workstation name is not always available and may be left blank in some cases._x000D_ _x000D_ The impersonation level field indicates the extent to which a process in the logon session can impersonate._x000D_ _x000D_ The authentication information fields provide detailed information about this specific logon request._x000D_ - Logon GUID is a unique identifier that can be used to correlate this event with a KDC event._x000D_ - Transited services indicate which intermediate services have participated in this logon request._x000D_ - Package name indicates which sub-protocol was used among the NTLM protocols._x000D_ - Key length indicates the length of the generated session key. This will be 0 if no session key was requested."
A13: Wazuh (default) | B13: 1 | C13: 1 | D13: 45744.661 | E13: suricata | F13: low | G13: 3 | H13: Informational Suricata Alert: ET INFO Packed Executable Download | I13: {"timestamp":"2025-03-28T14:51:59.523916+0000","flow_id":2219859327676154,"in_iface":"ens5","event_type":"alert","src_ip":"23.55.161.142","src_port":80,"dest_ip":"10.0.6.29","dest_port":56841,"proto":"TCP","pkt_src":"vxlan encapsulation","metadata":{"flowbits":["exe.no.referer","ET.INFO.WindowsUpdate"]},"community_id":"1:Gfnx5z3j8E1NITvlFD7PJA9oU60=","tx_id":0,"alert":{"action":"allowed","gid":1,"signature_id":2014819,"rev":5,"signature":"ET INFO Packed Executable Download","category":"Misc activity","severity":3,"metadata":{"confidence":["Medium"],"created_at":["2012_05_30"],"performance_impact":["Moderate"],"signature_severity":["Informational"],"updated_at":["2024_04_08"]}},"tunnel":{"src_ip":"10.0.6.29","src_port":65477,"dest_ip":"10.0.6.9","dest_port":4789,"proto":"UDP","depth":1,"pkt_src":"wire/pcap"},"http":{"hostname":"au.download.windowsupdate.com","url":"/c/msdownload/update/software/defu/2025/03/am_delta_patch_1.425.274.0_190b7f6379ebb86967af8cefe6f392488733b2dd.exe","http_user_agent":"Microsoft-Delivery-Optimization/10.0","http_content_type":"application/octet-stream","content_range":{"raw":"bytes 0-1048575/1541744","start":0,"end":1048575,"size":1541744},"http_method":"GET","protocol":"HTTP/1.1","status":206,"length":42404},"files":[{"filename":"/c/msdownload/update/software/defu/2025/03/am_delta_patch_1.425.274.0_190b7f6379ebb86967af8cefe6f392488733b2dd.exe","gaps":false,"state":"UNKNOWN","stored":false,"size":42404,"start":0,"end":1048575,"tx_id":0}],"app_proto":"http","direction":"to_client","flow":{"pkts_toserver":9,"pkts_toclient":37,"bytes_toserver":713,"bytes_toclient":51546,"start":"2025-03-28T14:51:59.516851+0000","src_ip":"10.0.6.29","dest_ip":"23.55.161.142","src_port":56841,"dest_port":80},"capture_file":"/var/log/suricata/nsm_data//log.pcap.1743173481","source":"suricata"}
... A342: Wazuh (default) | B342: 1 | C342: 1 | D342: 45744.68 | E342: DC1 | F342: low | G342: 3 | H342: Windows Logon Success | I342: "An account was successfully logged on._x000D_ _x000D_ Subject:_x000D_ Security ID: S-1-0-0_x000D_ Account Name: -_x000D_ Account Domain: -_x000D_ Logon ID: 0x0_x000D_ _x000D_ Logon Information:_x000D_ Logon Type: 3_x000D_ Restricted Admin Mode: -_x000D_ Virtual Account: No_x000D_ Elevated Token: Yes_x000D_ _x000D_ Impersonation Level: Impersonation_x000D_ _x000D_ New Logon:_x000D_ Security ID: S-1-5-18_x000D_ Account Name: DC1$_x000D_ Account Domain: PLUMETECH.LOCAL_x000D_ Logon ID: 0xC75F50_x000D_ Linked Logon ID: 0x0_x000D_ Network Account Name: -_x000D_ Network Account Domain: -_x000D_ Logon GUID: {59f6ceb3-4310-9443-e45f-079b56d5b2b9}_x000D_ _x000D_ Process Information:_x000D_ Process ID: 0x0_x000D_ Process Name: -_x000D_ _x000D_ Network Information:_x000D_ Workstation Name: -_x000D_ Source Network Address: ::1_x000D_ Source Port: 51714_x000D_ _x000D_ Detailed Authentication Information:_x000D_ Logon Process: Kerberos_x000D_ Authentication Package: Kerberos_x000D_ Transited Services: -_x000D_ Package Name (NTLM only): -_x000D_ Key Length: 0_x000D_ _x000D_ This event is generated when a logon session is created. It is generated on the computer that was accessed._x000D_ _x000D_ The subject fields indicate the account on the local system which requested the logon. This is most commonly a service such as the Server service, or a local process such as Winlogon.exe or Services.exe._x000D_ _x000D_ The logon type field indicates the kind of logon that occurred. The most common types are 2 (interactive) and 3 (network)._x000D_ _x000D_ The New Logon fields indicate the account for whom the new logon was created, i.e. the account that was logged on._x000D_ _x000D_ The network fields indicate where a remote logon request originated. Workstation name is not always available and may be left blank in some cases._x000D_ _x000D_ The impersonation level field indicates the extent to which a process in the logon session can impersonate._x000D_ _x000D_ The authentication information fields provide detailed information about this specific logon request._x000D_ - Logon GUID is a unique identifier that can be used to correlate this event with a KDC event._x000D_ - Transited services indicate which intermediate services have participated in this logon request._x000D_ - Package name indicates which sub-protocol was used among the NTLM protocols._x000D_ - Key length indicates the length of the generated session key. This will be 0 if no session key was requested."

Sheet vendor_a_edr_team6_run2
A1: Rule Origin | B1: Attack Confidence Pentester A | C1: Attack Confidence Pentester B | D1: timestamp | E1: Host | F1: severity_name | G1: severity | H1: description | I1: cmdline | J1: files_written | K1: entities

Sheet vendor_a_idp_team6_run2
A1: Rule Origin | B1: Attack Confidence Pentester A | C1: Attack Confidence Pentester B | D1: process.start | E1: Vendor.SeverityName | F1: source.ip | G1: source.user.name | H1: user.target.name | I1: threat.indicator.description | J1: Vendor.EventSourceName | K1: Tactic | L1: Technique | M1: @rawstring
A2: Vendor A EDR (IDP) | B2: 5 | C2: 5 | D2: 45744.676 | E2: Informational | F2: 10.0.6.30 | G2: manuel@PLUMETECH.LOCAL | H2: manuel | I2: A user executed a self-request for a Ticket Granting Service (TGS), following a Kerberos certificate-based authentication, which might indicate a malicious activity | J2: Anomalous certificate-based authentication (unusual TGS request)IDPEvent | K2: TA0006 Credential Access | L2: T1003 OS Credential Dumping | M2: {"Ngsiem.alert.id":"9374a063cba648ff951d57ebc35eb15e:ind:9374a063cba648ff951d57ebc35eb15e:D7C5AE63-91EC-4F97-B06B-E4FE85185F7D","Ngsiem.detection.id":"","Ngsiem.event.data_domain":"Identity","Ngsiem.event.id":"93782fc46b8e4631b2b8d0b7b7d89be2","Ngsiem.event.product":"Falcon Identity Protection","Ngsiem.event.vendor":"CrowdStrike","Ngsiem.indicator.data_domain[0]":"Identity","Ngsiem.indicator.display_name":"Anomalous certificate-based authentication (unusual TGS request)","Ngsiem.indicator.id":"93782fc46b8e4631b2b8d0b7b7d89be2","Ngsiem.indicator.source_product[0]":"Falcon Identity Protection","Ngsiem.indicator.source_vendor[0]":"CrowdStrike","Ngsiem.metadata":"{\"Metadata\":{}}","Ngsiem.pattern.id":"51162","Ngsiem.properties":"[{\"EntitySummary:user_sid\":\"S-1-5-21-514844351-3181471642-2638765006-1103\",\"EntitySummary:username\":\"manuel@PLUMETECH.LOCAL\",\"GUID\":\"BB8DBD6B-9FAA-3A28-9AF8-6F79006B765B\",\"UIVertexType\":\"user\",\"UserName\":\"manuel@PLUMETECH.LOCAL\",\"UserSID\":\"S-1-5-21-514844351-3181471642-2638765006-1103\",\"domain\":\"User\",\"id\":\"S-1-5-21-514844351-3181471642-2638765006-1103\"},{\"EntitySummary:ip\":\"10.0.6.30\",\"IPAddress\":\"10.0.6.30\",\"UIVertexType\":\"ip_address\",\"domain\":\"IpAddress\",\"id\":\"10.0.6.30\"}]","Ngsiem.type":"Indicator","Vendor.ActivityId":"1EE28E2F-C5DF-4B60-AB38-93EF08346C44","Vendor.ContextTimeStamp":"133876487350000000","Vendor.DetectID":"9374a063cba648ff951d57ebc35eb15e:ind:9374a063cba648ff951d57ebc35eb15e:D7C5AE63-91EC-4F97-B06B-E4FE85185F7D","Vendor.EventName":"CertificateBasedAuthenticationSelfUserTicketIndicator","Vendor.EventSourceName":"Anomalous certificate-based authentication (unusual TGS request)IDPEvent","Vendor.EventType":"IdpDetectionSummaryEvent","Vendor.FalconHostLink":"https://falcon.eu-1.crowdstrike.com/identity-protection/detections/9374a063cba648ff951d57ebc35eb15e:ind:9374a063cba648ff951d57ebc35eb15e:D7C5AE63-91EC-4F97-B06B-E4FE85185F7D?_cid=g05000u56ylbfaurdzjj72wbjahc2rdu","Vendor.Objective":"Gain Access","Vendor.PatternID":"51162","Vendor.SeverityName":"Informational","Vendor.SourceEndpointAccountObjectGuid":"BB8DBD6B-9FAA-3A28-9AF8-6F79006B765B","Vendor.TargetServiceAccessIdentifier":"manuel","event.action":"CertificateBasedAuthenticationSelfUserTicketIndicator","event.category[0]":"threat","event.created":"2025-03-28T15:18:55Z","event.severity":"60","event.type[0]":"indicator","process.end":"2025-03-28T15:14:08Z","process.start":"2025-03-28T15:14:08Z","rule.id":"999998","rule.version":"0","source.ip":"10.0.6.30","source.user.domain":"PLUMETECH.LOCAL","source.user.id":"S-1-5-21-514844351-3181471642-2638765006-1103","source.user.name":"manuel@PLUMETECH.LOCAL","threat.framework":"MITRE ATT\u0026CK","threat.indicator.description":"A user executed a self-request for a Ticket Granting Service (TGS), following a Kerberos certificate-based authentication, which might indicate a malicious activity","threat.indicator.first_seen":"2025-03-28T15:20:00Z","threat.indicator.last_seen":"2025-03-28T15:20:00Z","threat.indicator.modified_at":"2025-03-28T15:20:00.897478537Z","threat.indicator.name":"Anomalous certificate-based authentication (unusual TGS request)","threat.indicator.provider":"crowdstrike.indicators","threat.tactic.id[0]":"TA0006","threat.tactic.name[0]":"Credential Access","threat.technique.id[0]":"T1003","threat.technique.name[0]":"OS Credential Dumping","trace.id":"7d3d782a-dbcd-4091-9611-3e67585a8dec","user.target.name":"manuel"}
A3: Vendor A EDR (IDP) | B3: 5 | C3: 5 | D3: 45744.676 | E3: Informational | F3: 10.0.6.30 | G3: debbie@PLUMETECH.LOCAL | H3: manuel@PLUMETECH.LOCAL | I3: A lower-privileged entity performed an unusual Kerberos certificate-based authentication to a higher-privileged entity, which might indicate a malicious activity | J3: Anomalous certificate-based authentication (user mismatch)IDPEvent | K3: TA0006 Credential Access | L3: T1649 Steal or Forge Authentication Certificates | M3: {"Ngsiem.alert.id":"9374a063cba648ff951d57ebc35eb15e:ind:9374a063cba648ff951d57ebc35eb15e:421B6F81-505E-4E7B-B1F7-D09DA3DECC0C","Ngsiem.detection.id":"","Ngsiem.event.data_domain":"Identity","Ngsiem.event.id":"3db125a285fa40b590847cc379e7b647","Ngsiem.event.product":"Falcon Identity Protection","Ngsiem.event.vendor":"CrowdStrike","Ngsiem.indicator.data_domain[0]":"Identity","Ngsiem.indicator.display_name":"Anomalous certificate-based authentication (user mismatch)","Ngsiem.indicator.id":"3db125a285fa40b590847cc379e7b647","Ngsiem.indicator.source_product[0]":"Falcon Identity Protection","Ngsiem.indicator.source_vendor[0]":"CrowdStrike","Ngsiem.metadata":"{\"Metadata\":{}}","Ngsiem.pattern.id":"51161","Ngsiem.properties":"[{\"EntitySummary:user_sid\":\"S-1-5-21-514844351-3181471642-2638765006-1105\",\"EntitySummary:username\":\"debbie@PLUMETECH.LOCAL\",\"GUID\":\"BB8DBD6B-9FAA-3A28-9AF8-6F79006B765B\",\"UIVertexType\":\"user\",\"UserName\":\"debbie@PLUMETECH.LOCAL\",\"UserSID\":\"S-1-5-21-514844351-3181471642-2638765006-1105\",\"domain\":\"User\",\"id\":\"S-1-5-21-514844351-3181471642-2638765006-1105\"},{\"EntitySummary:ip\":\"10.0.6.30\",\"IPAddress\":\"10.0.6.30\",\"UIVertexType\":\"ip_address\",\"domain\":\"IpAddress\",\"id\":\"10.0.6.30\"}]","Ngsiem.type":"Indicator","Vendor.ActivityId":"944AB1CE-34CB-42B8-B935-5ABAC1007254","Vendor.ContextTimeStamp":"133876487350000000","Vendor.DetectID":"9374a063cba648ff951d57ebc35eb15e:ind:9374a063cba648ff951d57ebc35eb15e:421B6F81-505E-4E7B-B1F7-D09DA3DECC0C","Vendor.EventName":"CertificateBasedAuthenticationUserMismatchIndicator","Vendor.EventSourceName":"Anomalous certificate-based authentication (user mismatch)IDPEvent","Vendor.EventType":"IdpDetectionSummaryEvent","Vendor.FalconHostLink":"https://falcon.eu-1.crowdstrike.com/identity-protection/detections/9374a063cba648ff951d57ebc35eb15e:ind:9374a063cba648ff951d57ebc35eb15e:421B6F81-505E-4E7B-B1F7-D09DA3DECC0C?_cid=g05000u56ylbfaurdzjj72wbjahc2rdu","Vendor.Objective":"Gain Access","Vendor.PatternID":"51161","Vendor.SeverityName":"Informational","Vendor.SourceEndpointAccountObjectGuid":"BB8DBD6B-9FAA-3A28-9AF8-6F79006B765B","event.action":"CertificateBasedAuthenticationUserMismatchIndicator","event.category[0]":"threat","event.created":"2025-03-28T15:18:55Z","event.severity":"60","event.type[0]":"indicator","process.end":"2025-03-28T15:14:08Z","process.start":"2025-03-28T15:14:08Z","rule.id":"999998","rule.version":"0","source.ip":"10.0.6.30","source.user.domain":"PLUMETECH.LOCAL","source.user.id":"S-1-5-21-514844351-3181471642-2638765006-1105","source.user.name":"debbie@PLUMETECH.LOCAL","threat.framework":"MITRE ATT\u0026CK","threat.indicator.description":"A lower-privileged entity performed an unusual Kerberos certificate-based authentication to a higher-privileged entity, which might indicate a malicious activity","threat.indicator.first_seen":"2025-03-28T15:19:59Z","threat.indicator.last_seen":"2025-03-28T15:19:59Z","threat.indicator.modified_at":"2025-03-28T15:19:59.722848154Z","threat.indicator.name":"Anomalous certificate-based authentication (user mismatch)","threat.indicator.provider":"crowdstrike.indicators","threat.tactic.id[0]":"TA0006","threat.tactic.name[0]":"Credential Access","threat.technique.id[0]":"T1649","threat.technique.name[0]":"Steal or Forge Authentication Certificates","trace.id":"f5a3bcad-8cd6-4a93-9686-322637679043","user.target.name":"manuel@PLUMETECH.LOCAL"}
A4: Vendor A EDR (IDP) | B4: 5 | C4: 5 | D4: 45744.676 | E4: Informational | F4: 10.0.6.30 | G4: manuel@PLUMETECH.LOCAL | H4: manuel | I4: A user performed an anomalous certificate authentication, which might indicate suspicious activity originating from the source endpoint | J4: Anomalous certificate-based authenticationIDPEvent | K4: TA0006 Credential Access | L4: T1649 Steal or Forge Authentication Certificates | M4: {"Ngsiem.alert.id":"9374a063cba648ff951d57ebc35eb15e:ind:9374a063cba648ff951d57ebc35eb15e:613BA3BD-AA2B-4585-A64F-17A932E2985F","Ngsiem.detection.id":"","Ngsiem.event.data_domain":"Identity","Ngsiem.event.id":"2ee47a50e7734019b166be464dea3134","Ngsiem.event.product":"Falcon Identity Protection","Ngsiem.event.vendor":"CrowdStrike","Ngsiem.indicator.data_domain[0]":"Identity","Ngsiem.indicator.display_name":"Anomalous certificate-based authentication","Ngsiem.indicator.id":"2ee47a50e7734019b166be464dea3134","Ngsiem.indicator.source_product[0]":"Falcon Identity Protection","Ngsiem.indicator.source_vendor[0]":"CrowdStrike","Ngsiem.metadata":"{\"Metadata\":{}}","Ngsiem.pattern.id":"51160","Ngsiem.properties":"[{\"EntitySummary:user_sid\":\"S-1-5-21-514844351-3181471642-2638765006-1103\",\"EntitySummary:username\":\"manuel@PLUMETECH.LOCAL\",\"GUID\":\"BB8DBD6B-9FAA-3A28-9AF8-6F79006B765B\",\"UIVertexType\":\"user\",\"UserName\":\"manuel@PLUMETECH.LOCAL\",\"UserSID\":\"S-1-5-21-514844351-3181471642-2638765006-1103\",\"domain\":\"User\",\"id\":\"S-1-5-21-514844351-3181471642-2638765006-1103\"},{\"EntitySummary:ip\":\"10.0.6.30\",\"IPAddress\":\"10.0.6.30\",\"UIVertexType\":\"ip_address\",\"domain\":\"IpAddress\",\"id\":\"10.0.6.30\"}]","Ngsiem.type":"Indicator","Vendor.ActivityId":"944AB1CE-34CB-42B8-B935-5ABAC1007254","Vendor.ContextTimeStamp":"133876487350000000","Vendor.DetectID":"9374a063cba648ff951d57ebc35eb15e:ind:9374a063cba648ff951d57ebc35eb15e:613BA3BD-AA2B-4585-A64F-17A932E2985F","Vendor.EventName":"CertificateBasedAuthenticationIndicator","Vendor.EventSourceName":"Anomalous certificate-based authenticationIDPEvent","Vendor.EventType":"IdpDetectionSummaryEvent","Vendor.FalconHostLink":"https://falcon.eu-1.crowdstrike.com/identity-protection/detections/9374a063cba648ff951d57ebc35eb15e:ind:9374a063cba648ff951d57ebc35eb15e:613BA3BD-AA2B-4585-A64F-17A932E2985F?_cid=g05000u56ylbfaurdzjj72wbjahc2rdu","Vendor.Objective":"Gain Access","Vendor.PatternID":"51160","Vendor.SeverityName":"Informational","Vendor.SourceEndpointAccountObjectGuid":"BB8DBD6B-9FAA-3A28-9AF8-6F79006B765B","event.action":"CertificateBasedAuthenticationIndicator","event.category[0]":"threat","event.created":"2025-03-28T15:18:55Z","event.severity":"40","event.type[0]":"indicator","process.end":"2025-03-28T15:14:08Z","process.start":"2025-03-28T15:14:08Z","rule.id":"999998","rule.version":"0","source.ip":"10.0.6.30","source.user.domain":"PLUMETECH.LOCAL","source.user.id":"S-1-5-21-514844351-3181471642-2638765006-1103","source.user.name":"manuel@PLUMETECH.LOCAL","threat.framework":"MITRE ATT\u0026CK","threat.indicator.description":"A user performed an anomalous certificate authentication, which might indicate suspicious activity originating from the source endpoint","threat.indicator.first_seen":"2025-03-28T15:19:59Z","threat.indicator.last_seen":"2025-03-28T15:19:59Z","threat.indicator.modified_at":"2025-03-28T15:19:59.710022875Z","threat.indicator.name":"Anomalous certificate-based authentication","threat.indicator.provider":"crowdstrike.indicators","threat.tactic.id[0]":"TA0006","threat.tactic.name[0]":"Credential Access","threat.technique.id[0]":"T1649","threat.technique.name[0]":"Steal or Forge Authentication Certificates","trace.id":"9eb99c5c-e7f6-4a14-8854-3133b3ef246b","user.target.name":"manuel"}

Sheet vendor_b_nids_team6_run2_objIT
A1: Rule Origin | B1: Attack Confidence Pentester A | C1: Attack Confidence Pentester B | D1: SEVERITY | E1: ID | F1: OCCURRED_AT | G1: TYPE | H1: DETECTION_QUADS | I1: SUMMARY | J1: CONTENT | K1: DETECTION | L1: ASSET_IDS | M1: SOURCE_HOST_NAME | N1: DESTINATION_HOST_NAME | O1: SOURCE_IP | P1: DESTINATION_IP | Q1: OTHER_IP | R1: SOURCE | S1: PACKET_CAPTURE_STATE
A2: Vendor B NIDS (default) | B2: 1 | C2: 1 | D2: Low | E2: 36734 | F2: 45744.663 | G2: Communication | H2: Configuration | I2: Detected 15 NewX509Certificate between 2025-03-28T14:45:57.707Z and 2025-03-28T14:54:56.456Z | J2: Sample NewX509Certificate values include: server: 20.97.190.220, 20.12.23.50, 142.250.184.195, 4.154.131.224, 3.160.150.90, 20.163.45.188, 40.69.70.68, 13.74.186.119, 20.189.173.9, 13.74.142.6; subject: , C=US, ST=WA, L=Redmond, O=Microsoft, OU=DSP, CN=*.prod.do.dsp.mp.microsoft.com, C=US, ST=WA, L=Redmond, O=Microsoft, OU=DSP, CN=fe2cr.update.microsoft.com, C=US, ST=Washington, L=Redmond, O=Microsoft Corporation, CN=login.live.com; not_before: , 2025-03-16T00:00:00Z, 2025-03-04T20:39:31Z, 2024-11-07T19:28:51Z; server_asset_id: 4111, 4110, 2808, 2615, 4107, 4106, 4104, 4114, 4108, 4113; dst__port: ('',); dns: ; uuid: b91bb837-987b-43a2-8b52-a156a058231f, a2f171bb-4453-40ca-abfd-fa839f5a05e9, 91fa61c2-2911-4be6-9a1a-4f1af98386d2, 6497950e-f3b5-46b0-b687-2b5743e15274, e13fb67a-c428-41de-a8f0-3bf3f2548ed5, 0003e30e-6ef5-4c73-b25e-c4c219cd855f, 4246147b-f108-4d54-ae6c-fd439f053950, 55e95481-c276-4f3f-b6eb-03c00ffc9f46, 00e4e171-600d-4dd8-b07e-3bf62480e017, 68711d39-e415-476a-ac5a-d39f6a3ad1ad; issuer: , C=US, ST=Washington, L=Redmond, O=Microsoft Corporation, CN=Microsoft ECC Content Distribution Secure Server CA 2.1, C=US, ST=Washington, L=Redmond, O=Microsoft Corporation, CN=Microsoft ECC Update Secure Server CA 2.1, C=US, O=DigiCert Inc, CN=DigiCert SHA2 Secure Server CA; client_asset_id: 1680, 1905, 50, 1841, 46, 1916, 1772, 1746, 1801, 1754; src__mac: ; not_after: , 2025-11-07T19:28:51Z, 2026-03-04T20:39:31Z, 2025-09-16T23:59:59Z; dst__mac: ; protocol: ; dst__ip: ; client: 10.0.1.12, 10.0.1.29, 10.0.6.29, 10.0.7.29, 10.0.4.30, 10.0.8.30, 10.0.7.12, 10.0.6.11, 10.0.7.11, 10.0.10.29; src__port: ('',); src__ip: ; | K2: X509 Certificate First Seen | L2: 1754,1841,1680,46,1772,1746,1916,1801,1905,50,4107,4111,4110,2808,2615,4106,4104,4114,4108,4113 | O2: 13.32.99.21,20.163.45.188,40.69.70.68,20.190.159.68,20.3.187.198,184.25.50.128,3.160.150.90,20.189.173.9,20.97.190.220,4.154.131.224 | P2: 10.0.6.11,10.0.7.12,10.0.7.29,10.0.1.12,10.0.7.11,10.0.6.29,10.0.8.30,10.0.10.29,10.0.4.30,10.0.2.29 | R2: b91bb837-987b-43a2-8b52-a156a058231f, a2f171bb-4453-40ca-abfd-fa839f5a05e9, 91fa61c2-2911-4be6-9a1a-4f1af98386d2, 6497950e-f3b5-46b0-b687-2b5743e15274, e13fb67a-c428-41de-a8f0-3bf3f2548ed5, 0003e30e-6ef5-4c73-b25e-c4c219cd855f, 4246147b-f108-4d54-ae6c-fd439f053950, 55e95481-c276-4f3f-b6eb-03c00ffc9f46, 00e4e171-600d-4dd8-b07e-3bf62480e017, 68711d39-e415-476a-ac5a-d39f6a3ad1ad
A3: Vendor B NIDS (default) | B3: 1 | C3: 1 | D3: Low | E3: 36740 | F3: 45744.663 | G3: Asset | H3: Configuration | I3: Detected 19 NewUserAgent between 2025-03-28T14:45:14.327Z and 2025-03-28T14:54:56.478Z | J3: Sample NewUserAgent values include: dst__port: ('',); uuid: 03d27bee-7c90-497b-956e-2ccfdf2d3776, 0a059ae3-60e4-41b2-a23e-c5281d9c7bae, 192f2110-36cc-456d-93ad-7d4a96502513, 024e851a-4fa8-49b0-9d12-c0ed966bb462, 0008335e-1627-45d3-9754-28637665152d, 07317a54-fedf-4e94-b299-8f22abc87ef4, 0034a611-d016-44e8-96ae-172c793f333f, 0484cd27-ed2f-4fdf-bf60-90e9c90932aa, c2e29799-470f-42ae-b022-2a6420d8f07f, 1aaac9d8-9dd3-49e5-b8cc-2b2e22c6c6e1; src__mac: ; src_ip: 10.0.1.12, 10.0.1.29, 10.0.6.29, 10.0.7.29, 10.0.7.12, 10.0.6.12, 10.0.2.11, 10.0.1.11, 10.0.2.29; dst__mac: ; protocol: ; src_asset_id: 1680, 45, 48, 1841, 50, 46, 1746, 1810, 44; dst__ip: ; src__port: ('',); user_agent: Microsoft-Delivery-Optimization/10.0, Microsoft BITS/7.8, Microsoft Edge Update/1.3.195.45;winhttp, Microsoft-CryptoAPI/10.0, Windows-Update-Agent/10.0.10011.16384 Client-Protocol/2.51; src__ip: ; | K3: User Agent First Seen | L3: 1841,1810,1680,46,44,1746,45,48,50 | Q3: 10.0.7.12,10.0.6.12,10.0.7.29,10.0.1.12,10.0.1.29,10.0.6.29,10.0.1.11,10.0.2.11,10.0.2.29 | R3: 03d27bee-7c90-497b-956e-2ccfdf2d3776, 0a059ae3-60e4-41b2-a23e-c5281d9c7bae, 192f2110-36cc-456d-93ad-7d4a96502513, 024e851a-4fa8-49b0-9d12-c0ed966bb462, 0008335e-1627-45d3-9754-28637665152d, 07317a54-fedf-4e94-b299-8f22abc87ef4, 0034a611-d016-44e8-96ae-172c793f333f, 0484cd27-ed2f-4fdf-bf60-90e9c90932aa, c2e29799-470f-42ae-b022-2a6420d8f07f, 1aaac9d8-9dd3-49e5-b8cc-2b2e22c6c6e1
A4: Vendor B NIDS (default) | B4: 5 | C4: 5 | D4: Medium | E4: 37628 | F4: 45744.677 | G4: Indicator | H4: Indicator | I4: Evil-WinRM User Agent | J4: Evil-WinRM User Agent | K4: WinRM Signatures | L4: 1898,1754 | O4: 10.0.6.30 | P4: 10.0.6.11 | R4: Network Traffic
A5: Vendor B NIDS (default) | B5: 5 | C5: 5 | D5: Medium | E5: 37627 | F5: 45744.677 | G5: Indicator | H5: Indicator | I5: Evil-WinRM User Agent Rapid Usage | J5: Evil-WinRM User Agent Rapid Usage | K5: WinRM Signatures | L5: 1898,1754 | O5: 10.0.6.30 | P5: 10.0.6.11 | R5: Network Traffic
A6: Vendor B NIDS (default) | B6: 5 | C6: 5 | D6: Low | E6: 37494 | F6: 45744.671 | G6: Communication | H6: Indicator | I6: Failed HTTP Logon | J6: Asset 1810 (10.0.6.12) returned an HTTP response code of 403 'Forbidden' to asset 1898 (10.0.6.30), which represents a failed logon attempt via HTTP by asset 1898. Logon attempts that result in HTTP status codes such as 401 'Unauthorized', 403 'Forbidden', or 407 'Proxy Authentication Required' can occur legitimately when users mistype credentials or attempt to access resources they are not authorized to use; however, they can also be indicative of malicious activities, such as unauthorized access attempts, brute force attacks, or the misuse of stolen credentials, where adversaries are testing access controls and trying to gain illicit entry into systems. | K6: HTTP Auth Failure | L6: 1898,1810 | O6: 10.0.6.12 | P6: 10.0.6.30 | R6: d88a5fac-8719-414f-9e6f-d6373fb7143a
